2023-07-12 20:42:37.295514: I tensorflow/core/platform/cpu_feature_guard.cc:182] This TensorFlow binary is optimized to use available CPU instructions in performance-critical operations.
To enable the following instructions: AVX2 FMA, in other operations, rebuild TensorFlow with the appropriate compiler flags.
2023-07-12 20:42:38.829356: W tensorflow/compiler/tf2tensorrt/utils/py_utils.cc:38] TF-TRT Warning: Could not find TensorRT
2023-07-12 20:42:42.591809: E tensorflow/compiler/xla/stream_executor/cuda/cuda_driver.cc:266] failed call to cuInit: CUDA_ERROR_NO_DEVICE: no CUDA-capable device is detected
INFO flwr 2023-07-12 20:42:43,456 | grpc.py:50 | Opened insecure gRPC connection (no certificates were passed)
DEBUG flwr 2023-07-12 20:42:43,471 | connection.py:39 | ChannelConnectivity.IDLE
DEBUG flwr 2023-07-12 20:42:43,475 | connection.py:39 | ChannelConnectivity.CONNECTING
DEBUG flwr 2023-07-12 20:42:43,740 | connection.py:39 | ChannelConnectivity.TRANSIENT_FAILURE
DEBUG flwr 2023-07-12 20:42:43,944 | connection.py:113 | gRPC channel closed
Traceback (most recent call last):
  File "/home/vtn_ubuntu/ttu/spring23/working_project/AsynFl/flower/client_235_cpu.py", line 129, in <module>
    start_client(args)
  File "/home/vtn_ubuntu/ttu/spring23/working_project/AsynFl/flower/client_235_cpu.py", line 116, in start_client
    fl.client.start_numpy_client(server_address=args.address, client=CifarClient())
  File "/home/vtn_ubuntu/miniconda3/envs/asynfed/lib/python3.9/site-packages/flwr/client/app.py", line 252, in start_numpy_client
    start_client(
  File "/home/vtn_ubuntu/miniconda3/envs/asynfed/lib/python3.9/site-packages/flwr/client/app.py", line 174, in start_client
    server_message = receive()
  File "/home/vtn_ubuntu/miniconda3/envs/asynfed/lib/python3.9/site-packages/flwr/client/grpc_client/connection.py", line 105, in <lambda>
    receive: Callable[[], ServerMessage] = lambda: next(server_message_iterator)
  File "/home/vtn_ubuntu/miniconda3/envs/asynfed/lib/python3.9/site-packages/grpc/_channel.py", line 475, in __next__
    return self._next()
  File "/home/vtn_ubuntu/miniconda3/envs/asynfed/lib/python3.9/site-packages/grpc/_channel.py", line 881, in _next
    raise self
grpc._channel._MultiThreadedRendezvous: <_MultiThreadedRendezvous of RPC that terminated with:
	status = StatusCode.UNAVAILABLE
	details = "failed to connect to all addresses; last error: UNKNOWN: ipv4:128.214.254.126:8080: Failed to connect to remote host: Connection refused"
	debug_error_string = "UNKNOWN:failed to connect to all addresses; last error: UNKNOWN: ipv4:128.214.254.126:8080: Failed to connect to remote host: Connection refused {created_time:"2023-07-12T20:42:43.739903825+07:00", grpc_status:14}"
>
